<?xml version="1.0" encoding="utf-8"?>

<robot name="surenaVgazebo" xmlns:xacro="http://www.ros.org/wiki/xacro">

<!-- This URDF was automatically created by SolidWorks to URDF Exporter! Originally created by Stephen Brawner (brawner@gmail.com) 
     Commit Version: 1.5.1-0-g916b5db  Build Version: 1.5.7152.31018
     For more information, please see http://wiki.ros.org/sw_urdf_exporter -->

  <link
    name="pelvis">
    <inertial>
      <origin
        xyz="-0.00217545783729715 0.000224163902766084 0.931395016004982"
        rpy="0 0 0" />
      <mass
        value="4.95204557596493" />
      <inertia
        ixx="0.0176440671739748"
        ixy="-1.02375863215085E-05"
        ixz="5.73242271540755E-06"
        iyy="0.00501907549843232"
        iyz="-6.72988733754336E-06"
        izz="0.020771026513756" />
    </inertial>
    <visual>
      <origin
        xyz="0 0 0"
        rpy="0 0 0" />
      <geometry>
        <mesh
          filename="package://surenaVgazebo/meshes/pelvis.STL" />
      </geometry>
      <material
        name="">
        <color
          rgba="0.752941176470588 0.752941176470588 0.752941176470588 1" />
      </material>
    </visual>
    <collision>
      <origin
        xyz="0 0 0"
        rpy="0 0 0" />
      <geometry>
        <mesh
          filename="package://surenaVgazebo/meshes/pelvis.STL" />
      </geometry>
    </collision>
    <gazebo reference="pelvis">
      <material>Gazebo/Yellow</material>
      <turnGravityOff>true</turnGravityOff>
    </gazebo>
  </link>
  
  
  <link
    name="RL_hip_yaw">
    <inertial>
      <origin
        xyz="-0.0762252739169794 0.000125508839245739 -0.0899852155691174"
        rpy="0 0 0" />
      <mass
        value="3.17293179372001" />
      <inertia
        ixx="0.00460178291391413"
        ixy="-3.00587826045875E-06"
        ixz="-2.51847760416055E-06"
        iyy="0.00361426922161703"
        iyz="-1.00259007387999E-05"
        izz="0.0035938959776605" />
    </inertial>
    <visual>
      <origin
        xyz="0 0 0"
        rpy="0 0 0" />
      <geometry>
        <mesh
          filename="package://surenaVgazebo/meshes/RL_hip_yaw.STL" />
      </geometry>
      <material
        name="">
        <color
          rgba="0.752941176470588 0.752941176470588 0.752941176470588 1" />
      </material>
    </visual>
    <collision>
      <origin
        xyz="0 0 0"
        rpy="0 0 0" />
      <geometry>
        <mesh
          filename="package://surenaVgazebo/meshes/RL_hip_yaw.STL" />
      </geometry>
    </collision>
    <gazebo reference="RL_hip_yaw">
      <material>Gazebo/Yellow</material>
      <turnGravityOff>true</turnGravityOff>
    </gazebo>
  </link>
  <joint
    name="RJ_hip_yaw"
    type="continuous">
    <origin
      xyz="0.017863 -0.1 0.87612"
      rpy="0 0 0" />
    <parent
      link="pelvis" />
    <child
      link="RL_hip_yaw" />
    <axis
      xyz="0 0 -1" />
    <limit effort="300.0" lower="-5000" upper="-5000" velocity="0.5"/>
  </joint>
  <transmission name="J1t">
    <type>transmission_interface/SimpleTransmission</type>
    <actuator name="motor1">
      <mechanicalReduction>1</mechanicalReduction>
      <hardwareInterface>hardware_interface/EffortJointInterface</hardwareInterface>
    </actuator>
    <joint name="RJ_hip_yaw">
      <hardwareInterface>hardware_interface/EffortJointInterface</hardwareInterface>
    </joint>
  </transmission>
  <link
    name="RL_hip_roll">
    <inertial>
      <origin
        xyz="2.22785334344708E-05 0.0247755120756775 -0.000135346544264198"
        rpy="0 0 0" />
      <mass
        value="2.44028233905691" />
      <inertia
        ixx="0.00231026647129809"
        ixy="-1.7622602877606E-05"
        ixz="1.33532503132314E-05"
        iyy="0.00397269360944497"
        iyz="3.22540666998572E-06"
        izz="0.00263954264914787" />
    </inertial>
    <visual>
      <origin
        xyz="0 0 0"
        rpy="0 0 0" />
      <geometry>
        <mesh
          filename="package://surenaVgazebo/meshes/RL_hip_roll.STL" />
      </geometry>
      <material
        name="">
        <color
          rgba="0.752941176470588 0.752941176470588 0.752941176470588 1" />
      </material>
    </visual>
    <collision>
      <origin
        xyz="0 0 0"
        rpy="0 0 0" />
      <geometry>
        <mesh
          filename="package://surenaVgazebo/meshes/RL_hip_roll.STL" />
      </geometry>
    </collision>
    <gazebo reference="RL_hip_roll">
      <material>Gazebo/Yellow</material>
      <turnGravityOff>true</turnGravityOff>
    </gazebo>
  </link>
  <joint
    name="RJ_hip_roll"
    type="continuous">
    <origin
      xyz="0 0 -0.1113"
      rpy="0 0 0" />
    <parent
      link="RL_hip_yaw" />
    <child
      link="RL_hip_roll" />
    <axis
      xyz="-1 0 0" />
    <limit effort="300.0" lower="-5000" upper="-5000" velocity="0.5"/>
  </joint>
  <transmission name="J2t">
    <type>transmission_interface/SimpleTransmission</type>
    <actuator name="motor2">
      <mechanicalReduction>1</mechanicalReduction>
      <hardwareInterface>hardware_interface/EffortJointInterface</hardwareInterface>
    </actuator>
    <joint name="RJ_hip_roll">
      <hardwareInterface>hardware_interface/EffortJointInterface</hardwareInterface>
    </joint>
  </transmission>
  <link
    name="RL_hip_pitch">
    <inertial>
      <origin
        xyz="-0.00045821623227639 0.0171178148193481 -0.183238234233956"
        rpy="0 0 0" />
      <mass
        value="5.07745417704148" />
      <inertia
        ixx="0.0064375403532907"
        ixy="2.07625176517652E-05"
        ixz="-2.22598666025542E-05"
        iyy="0.00780317590767482"
        iyz="9.77799922453546E-06"
        izz="0.00474032860537049" />
    </inertial>
    <visual>
      <origin
        xyz="0 0 0"
        rpy="0 0 0" />
      <geometry>
        <mesh
          filename="package://surenaVgazebo/meshes/RL_hip_pitch.STL" />
      </geometry>
      <material
        name="">
        <color
          rgba="0.752941176470588 0.752941176470588 0.752941176470588 1" />
      </material>
    </visual>
    <collision>
      <origin
        xyz="0 0 0"
        rpy="0 0 0" />
      <geometry>
        <mesh
          filename="package://surenaVgazebo/meshes/RL_hip_pitch.STL" />
      </geometry>
    </collision>
    <gazebo reference="RL_hip_pitch">
      <material>Gazebo/Yellow</material>
      <turnGravityOff>true</turnGravityOff>
    </gazebo>
  </link>
  <joint
    name="RJ_hip_pitch"
    type="continuous">
    <origin
      xyz="0 0 0"
      rpy="0 0 0" />
    <parent
      link="RL_hip_roll" />
    <child
      link="RL_hip_pitch" />
    <axis
      xyz="0 1 0" />
    <limit effort="300.0" lower="-5000" upper="-5000" velocity="0.5"/>
  </joint>
  <transmission name="J3t">
    <type>transmission_interface/SimpleTransmission</type>
    <actuator name="motor3">
      <mechanicalReduction>1</mechanicalReduction>
      <hardwareInterface>hardware_interface/EffortJointInterface</hardwareInterface>      
    </actuator>
    <joint name="RJ_hip_pitch">
      <hardwareInterface>hardware_interface/EffortJointInterface</hardwareInterface>
    </joint>
  </transmission>
  <link
    name="RL_knee_pitch">
    <inertial>
      <origin
        xyz="0.0017899880065982 0.00329834413534699 -0.0646835033521056"
        rpy="0 0 0" />
      <mass
        value="1.63398838912661" />
      <inertia
        ixx="0.00288680135410067"
        ixy="-1.67381259635436E-07"
        ixz="-2.24910995073404E-05"
        iyy="0.00314482281775824"
        iyz="9.78680551766758E-07"
        izz="0.00100110338991923" />
    </inertial>
    <visual>
      <origin
        xyz="0 0 0"
        rpy="0 0 0" />
      <geometry>
        <mesh
          filename="package://surenaVgazebo/meshes/RL_knee_pitch.STL" />
      </geometry>
      <material
        name="">
        <color
          rgba="0.752941176470588 0.752941176470588 0.752941176470588 1" />
      </material>
    </visual>
    <collision>
      <origin
        xyz="0 0 0"
        rpy="0 0 0" />
      <geometry>
        <mesh
          filename="package://surenaVgazebo/meshes/RL_knee_pitch.STL" />
      </geometry>
    </collision>
    <gazebo reference="RL_knee_pitch">
      <material>Gazebo/Yellow</material>
      <turnGravityOff>true</turnGravityOff>
    </gazebo>
  </link>
  <joint
    name="RJ_knee_pitch"
    type="continuous">
    <origin
      xyz="0 0 -0.35988"
      rpy="0 0 0" />
    <parent
      link="RL_hip_pitch" />
    <child
      link="RL_knee_pitch" />
    <axis
      xyz="0 1 0" />
    <limit effort="300.0" lower="-5000" upper="-5000" velocity="0.5"/>
  </joint>
  <transmission name="J4t">
    <type>transmission_interface/SimpleTransmission</type>
    <actuator name="motor4">
      <mechanicalReduction>1</mechanicalReduction>
      <hardwareInterface>hardware_interface/EffortJointInterface</hardwareInterface>
    </actuator>
    <joint name="RJ_knee_pitch">
      <hardwareInterface>hardware_interface/EffortJointInterface</hardwareInterface>
    </joint>
  </transmission>
  <link
    name="RL_ankle_pitch">
    <inertial>
      <origin
        xyz="-0.00489725000961184 0.00473538525417702 -0.000766172453700364"
        rpy="0 0 0" />
      <mass
        value="0.108340845963504" />
      <inertia
        ixx="9.14169347532508E-06"
        ixy="3.76489660257135E-09"
        ixz="1.36207024061369E-06"
        iyy="0.000122294989131605"
        iyz="1.82076506122421E-07"
        izz="0.000116703015789648" />
    </inertial>
    <visual>
      <origin
        xyz="0 0 0"
        rpy="0 0 0" />
      <geometry>
        <mesh
          filename="package://surenaVgazebo/meshes/RL_ankle_pitch.STL" />
      </geometry>
      <material
        name="">
        <color
          rgba="0.752941176470588 0.752941176470588 0.752941176470588 1" />
      </material>
    </visual>
    <collision>
      <origin
        xyz="0 0 0"
        rpy="0 0 0" />
      <geometry>
        <mesh
          filename="package://surenaVgazebo/meshes/RL_ankle_pitch.STL" />
      </geometry>
    </collision>
    <gazebo reference="RL_ankle_pitch">
      <material>Gazebo/Yellow</material>
      <turnGravityOff>true</turnGravityOff>
    </gazebo>
  </link>
  <joint
    name="RJ_ankle_pitch"
    type="continuous">
    <origin
      xyz="0 0 -0.34999"
      rpy="0 0 0" />
    <parent
      link="RL_knee_pitch" />
    <child
      link="RL_ankle_pitch" />
    <axis
      xyz="0 -1 0" />
    <limit effort="300.0" lower="-5000" upper="-5000" velocity="0.5"/>
  </joint>
  <transmission name="J5t">
    <type>transmission_interface/SimpleTransmission</type>
    <actuator name="motor5">
      <mechanicalReduction>1</mechanicalReduction>
      <hardwareInterface>hardware_interface/EffortJointInterface</hardwareInterface>
    </actuator>
    <joint name="RJ_ankle_pitch">
      <hardwareInterface>hardware_interface/EffortJointInterface</hardwareInterface>
    </joint>
  </transmission>
  <link
    name="RL_ankle_roll">
    <inertial>
      <origin
        xyz="0.0251782639001623 0.00293879309636647 -0.0400976969392328"
        rpy="0 0 0" />
      <mass
        value="1.80660460406209" />
      <inertia
        ixx="0.00309562856625343"
        ixy="-9.25756541165906E-07"
        ixz="5.40003129346676E-09"
        iyy="0.00734487579285686"
        iyz="-1.22595155654811E-08"
        izz="0.0103785967656656" />
    </inertial>
    <visual>
      <origin
        xyz="0 0 0"
        rpy="0 0 0" />
      <geometry>
        <mesh
          filename="package://surenaVgazebo/meshes/RL_ankle_roll.STL" />
      </geometry>
      <material
        name="">
        <color
          rgba="0.752941176470588 0.752941176470588 0.752941176470588 1" />
      </material>
    </visual>
    <collision>
      <origin
        xyz="0 0 0"
        rpy="0 0 0" />
      <geometry>
        <mesh
          filename="package://surenaVgazebo/meshes/RL_ankle_roll.STL" />
      </geometry>
    </collision>
    <gazebo reference="RL_ankle_roll">
      <material>Gazebo/Yellow</material>
      <turnGravityOff>true</turnGravityOff>
    </gazebo>
    <surface>
          <friction>
            <ode>
              <mu>1</mu>
              <mu2>1</mu2>
              <fdir1>0 0 1</fdir1>
              <slip1>0.0</slip1>
              <slip2>0.0</slip2>
            </ode>
          </friction>
          <contact>
               <ode>
                  <min_depth>5</min_depth>
                   <kp>1e8</kp>
               </ode>
          </contact>
    </surface>
  </link>
  <joint
    name="RJ_ankle_roll"
    type="continuous">
    <origin
      xyz="0 0 0"
      rpy="0 0 0" />
    <parent
      link="RL_ankle_pitch" />
    <child
      link="RL_ankle_roll" />
    <axis
      xyz="-1 0 0" />
    <limit effort="300.0" lower="-5000" upper="-5000" velocity="0.5"/>
  </joint>
  <transmission name="J6t">
    <type>transmission_interface/SimpleTransmission</type>
    <actuator name="motor6">
      <mechanicalReduction>1</mechanicalReduction>
      <hardwareInterface>hardware_interface/EffortJointInterface</hardwareInterface>
    </actuator>
    <joint name="RJ_ankle_roll">
      <hardwareInterface>hardware_interface/EffortJointInterface</hardwareInterface>
    </joint>
  </transmission>
  <link
    name="LL_hip_yaw">
    <inertial>
      <origin
        xyz="-0.0757112957097321 9.50188478069242E-05 -0.0900035578707153"
        rpy="0 0 0" />
      <mass
        value="3.17069652378066" />
      <inertia
        ixx="0.00459885030496593"
        ixy="-3.62984625055848E-06"
        ixz="-1.50781573446136E-06"
        iyy="0.00360667895144584"
        iyz="-7.15387295322081E-06"
        izz="0.0035985502859866" />
    </inertial>
    <visual>
      <origin
        xyz="0 0 0"
        rpy="0 0 0" />
      <geometry>
        <mesh
          filename="package://surenaVgazebo/meshes/LL_hip_yaw.STL" />
      </geometry>
      <material
        name="">
        <color
          rgba="0.752941176470588 0.752941176470588 0.752941176470588 1" />
      </material>
    </visual>
    <collision>
      <origin
        xyz="0 0 0"
        rpy="0 0 0" />
      <geometry>
        <mesh
          filename="package://surenaVgazebo/meshes/LL_hip_yaw.STL" />
      </geometry>
    </collision>
    <gazebo reference="LL_hip_yaw">
      <material>Gazebo/Yellow</material>
      <turnGravityOff>true</turnGravityOff>
    </gazebo>
  </link>
  <joint
    name="LJ_hip_yaw"
    type="continuous">
    <origin
      xyz="0.017863 0.1 0.87612"
      rpy="0 0 0" />
    <parent
      link="pelvis" />
    <child
      link="LL_hip_yaw" />
    <axis
      xyz="0 0 1" />
    <limit effort="300.0" lower="-5000" upper="-5000" velocity="0.5"/>
  </joint>
  <transmission name="J7t">
    <type>transmission_interface/SimpleTransmission</type>
    <actuator name="motor7">
      <mechanicalReduction>1</mechanicalReduction>
      <hardwareInterface>hardware_interface/EffortJointInterface</hardwareInterface>
    </actuator>
    <joint name="LJ_hip_yaw">
      <hardwareInterface>hardware_interface/EffortJointInterface</hardwareInterface>
    </joint>
  </transmission>
  <link
    name="LL_hip_roll">
    <inertial>
      <origin
        xyz="1.77858666269431E-05 -0.0247753062593557 6.5147281054917E-05"
        rpy="0 0 0" />
      <mass
        value="2.43804706933098" />
      <inertia
        ixx="0.0022975432152425"
        ixy="1.9029659833091E-05"
        ixz="-8.66817392481041E-06"
        iyy="0.00396976100139585"
        iyz="1.47126612687577E-06"
        izz="0.00264932994425984" />
    </inertial>
    <visual>
      <origin
        xyz="0 0 0"
        rpy="0 0 0" />
      <geometry>
        <mesh
          filename="package://surenaVgazebo/meshes/LL_hip_roll.STL" />
      </geometry>
      <material
        name="">
        <color
          rgba="0.752941176470588 0.752941176470588 0.752941176470588 1" />
      </material>
    </visual>
    <collision>
      <origin
        xyz="0 0 0"
        rpy="0 0 0" />
      <geometry>
        <mesh
          filename="package://surenaVgazebo/meshes/LL_hip_roll.STL" />
      </geometry>
    </collision>
    <gazebo reference="LL_hip_roll">
      <material>Gazebo/Yellow</material>
      <turnGravityOff>true</turnGravityOff>
    </gazebo>
  </link>
  <joint
    name="LJ_hip_roll"
    type="continuous">
    <origin
      xyz="0 0 -0.1113"
      rpy="0 0 0" />
    <parent
      link="LL_hip_yaw" />
    <child
      link="LL_hip_roll" />
    <axis
      xyz="1 0 0" />
    <limit effort="300.0" lower="-5000" upper="-5000" velocity="0.5"/>
  </joint>
  <transmission name="J8t">
    <type>transmission_interface/SimpleTransmission</type>
    <actuator name="motor8">
      <mechanicalReduction>1</mechanicalReduction>
      <hardwareInterface>hardware_interface/EffortJointInterface</hardwareInterface>
    </actuator>
    <joint name="LJ_hip_roll">
      <hardwareInterface>hardware_interface/EffortJointInterface</hardwareInterface>
    </joint>
  </transmission>
  <link
    name="LL_hip_pitch">
    <inertial>
      <origin
        xyz="-0.000372227589193863 -0.0144742792764355 -0.18073438160189"
        rpy="0 0 0" />
      <mass
        value="5.4207508687006" />
      <inertia
        ixx="0.00669509559692382"
        ixy="-2.37016259243835E-05"
        ixz="-7.91409486061681E-05"
        iyy="0.00837756280316209"
        iyz="-5.49284882343701E-06"
        izz="0.00506572121943718" />
    </inertial>
    <visual>
      <origin
        xyz="0 0 0"
        rpy="0 0 0" />
      <geometry>
        <mesh
          filename="package://surenaVgazebo/meshes/LL_hip_pitch.STL" />
      </geometry>
      <material
        name="">
        <color
          rgba="0.752941176470588 0.752941176470588 0.752941176470588 1" />
      </material>
    </visual>
    <collision>
      <origin
        xyz="0 0 0"
        rpy="0 0 0" />
      <geometry>
        <mesh
          filename="package://surenaVgazebo/meshes/LL_hip_pitch.STL" />
      </geometry>
    </collision>
    <gazebo reference="LL_hip_pitch">
      <material>Gazebo/Yellow</material>
      <turnGravityOff>true</turnGravityOff>
    </gazebo>
  </link>
  <joint
    name="LJ_hip_pitch"
    type="continuous">
    <origin
      xyz="0 0 0"
      rpy="0 0 0" />
    <parent
      link="LL_hip_roll" />
    <child
      link="LL_hip_pitch" />
    <axis
      xyz="0 1 0" />
    <limit effort="300.0" lower="-5000" upper="-5000" velocity="0.5"/>
  </joint>
  <transmission name="J9t">
    <type>transmission_interface/SimpleTransmission</type>
    <actuator name="motor9">
      <mechanicalReduction>1</mechanicalReduction>
      <hardwareInterface>hardware_interface/EffortJointInterface</hardwareInterface>
    </actuator>
    <joint name="LJ_hip_pitch">
      <hardwareInterface>hardware_interface/EffortJointInterface</hardwareInterface>
    </joint>
  </transmission>
  <link
    name="LL_knee_pitch">
    <inertial>
      <origin
        xyz="0.00197693520479513 -0.00329834983098574 -0.0646889527916195"
        rpy="0 0 0" />
      <mass
        value="1.63398839859012" />
      <inertia
        ixx="0.00288646848643183"
        ixy="2.0307110681928E-07"
        ixz="-2.24436027997729E-05"
        iyy="0.00314482282907816"
        iyz="-1.21747635603572E-06"
        izz="0.0010014362762353" />
    </inertial>
    <visual>
      <origin
        xyz="0 0 0"
        rpy="0 0 0" />
      <geometry>
        <mesh
          filename="package://surenaVgazebo/meshes/LL_knee_pitch.STL" />
      </geometry>
      <material
        name="">
        <color
          rgba="0.752941176470588 0.752941176470588 0.752941176470588 1" />
      </material>
    </visual>
    <collision>
      <origin
        xyz="0 0 0"
        rpy="0 0 0" />
      <geometry>
        <mesh
          filename="package://surenaVgazebo/meshes/LL_knee_pitch.STL" />
      </geometry>
    </collision>
    <gazebo reference="LL_knee_pitch">
      <material>Gazebo/Yellow</material>
      <turnGravityOff>true</turnGravityOff>
    </gazebo>
  </link>
  <joint
    name="LJ_knee_pitch"
    type="continuous">
    <origin
      xyz="4.0696E-05 0 -0.35988"
      rpy="0 0 0" />
    <parent
      link="LL_hip_pitch" />
    <child
      link="LL_knee_pitch" />
    <axis
      xyz="0 1 0" />
    <limit effort="300.0" lower="-5000" upper="-5000" velocity="0.5"/>
  </joint>
  <transmission name="J10t">
    <type>transmission_interface/SimpleTransmission</type>
    <actuator name="motor10">
      <mechanicalReduction>1</mechanicalReduction>
      <hardwareInterface>hardware_interface/EffortJointInterface</hardwareInterface>
    </actuator>
    <joint name="LJ_knee_pitch">
      <hardwareInterface>hardware_interface/EffortJointInterface</hardwareInterface>
    </joint>
  </transmission>
  <link
    name="LL_ankle_pitch">
    <inertial>
      <origin
        xyz="-0.00489725000960469 -0.00473538525416781 -0.000766172453700364"
        rpy="0 0 0" />
      <mass
        value="0.108340845963504" />
      <inertia
        ixx="9.14169347532509E-06"
        ixy="-3.76489669921809E-09"
        ixz="1.36207024061396E-06"
        iyy="0.000122294989131605"
        iyz="-1.82076506121227E-07"
        izz="0.000116703015789648" />
    </inertial>
    <visual>
      <origin
        xyz="0 0 0"
        rpy="0 0 0" />
      <geometry>
        <mesh
          filename="package://surenaVgazebo/meshes/LL_ankle_pitch.STL" />
      </geometry>
      <material
        name="">
        <color
          rgba="0.752941176470588 0.752941176470588 0.752941176470588 1" />
      </material>
    </visual>
    <collision>
      <origin
        xyz="0 0 0"
        rpy="0 0 0" />
      <geometry>
        <mesh
          filename="package://surenaVgazebo/meshes/LL_ankle_pitch.STL" />
      </geometry>
    </collision>
    <gazebo reference="LL_ankle_pitch">
      <material>Gazebo/Yellow</material>
      <turnGravityOff>true</turnGravityOff>
    </gazebo>
  </link>
  <joint
    name="LJ_ankle_pitch"
    type="continuous">
    <origin
      xyz="0 0 -0.34999"
      rpy="0 0 0" />
    <parent
      link="LL_knee_pitch" />
    <child
      link="LL_ankle_pitch" />
    <axis
      xyz="0 -1 0" />
    <limit effort="300.0" lower="-5000" upper="-5000" velocity="0.5"/>
  </joint>
  <transmission name="J11t">
    <type>transmission_interface/SimpleTransmission</type>
    <actuator name="motor11">
      <mechanicalReduction>1</mechanicalReduction>
      <hardwareInterface>hardware_interface/EffortJointInterface</hardwareInterface>
    </actuator>
    <joint name="LJ_ankle_pitch">
      <hardwareInterface>hardware_interface/EffortJointInterface</hardwareInterface>
    </joint>
  </transmission>
  <link
    name="LL_ankle_roll">
    <inertial>
      <origin
        xyz="0.0251696573984807 -0.00266108764646895 -0.04011942471265"
        rpy="0 0 0" />
      <mass
        value="1.80512900691448" />
      <inertia
        ixx="0.00309544993282126"
        ixy="-9.25753770737509E-07"
        ixz="5.40112168590014E-09"
        iyy="0.00734464783805675"
        iyz="-1.22604609109996E-08"
        izz="0.0103783901380754" />
    </inertial>
    <visual>
      <origin
        xyz="0 0 0"
        rpy="0 0 0" />
      <geometry>
        <mesh
          filename="package://surenaVgazebo/meshes/LL_ankle_roll.STL" />
      </geometry>
      <material
        name="">
        <color
          rgba="0.752941176470588 0.752941176470588 0.752941176470588 1" />
      </material>
    </visual>
    <collision>
      <origin
        xyz="0 0 0"
        rpy="0 0 0" />
      <geometry>
        <mesh
          filename="package://surenaVgazebo/meshes/LL_ankle_roll.STL" />
      </geometry>
    </collision>
    <gazebo reference="LL_ankle_roll">
      <material>Gazebo/Yellow</material>
      <turnGravityOff>true</turnGravityOff>
    </gazebo>
    <surface>
          <friction>
            <ode>
              <mu>1</mu>
              <mu2>1</mu2>
              <fdir1>0 0 1</fdir1>
              <slip1>0.0</slip1>
              <slip2>0.0</slip2>
            </ode>
          </friction>
          <contact>
               <ode>
                  <min_depth>5</min_depth>
                   <kp>1e8</kp>
               </ode>
          </contact>
    </surface>
  </link>
  <joint
    name="LJ_ankle_roll"
    type="continuous">
    <origin
      xyz="0 0 0"
      rpy="0 0 0" />
    <parent
      link="LL_ankle_pitch" />
    <child
      link="LL_ankle_roll" />
    <axis
      xyz="-1 0 0" />
    <limit effort="300.0" lower="-5000" upper="-5000" velocity="0.5"/>
  </joint>
  <transmission name="J12t">
    <type>transmission_interface/SimpleTransmission</type>
    <actuator name="motor12">
      <mechanicalReduction>1</mechanicalReduction>
      <hardwareInterface>hardware_interface/EffortJointInterface</hardwareInterface>
    </actuator>
    <joint name="LJ_ankle_roll">
      <hardwareInterface>hardware_interface/EffortJointInterface</hardwareInterface>
    </joint>
  </transmission>
  <link
    name="L_waist_yaw">
    <inertial>
      <origin
        xyz="0.0336149996090985 1.5189227452618E-09 0.0248920105646678"
        rpy="0 0 0" />
      <mass
        value="0.376935800554799" />
      <inertia
        ixx="0.00014699867644807"
        ixy="2.2844861508623E-15"
        ixz="-1.44176043926084E-05"
        iyy="0.000438369411093624"
        iyz="-2.92069113942974E-18"
        izz="0.000493813327740214" />
    </inertial>
    <visual>
      <origin
        xyz="0 0 0"
        rpy="0 0 0" />
      <geometry>
        <mesh
          filename="package://surenaVgazebo/meshes/L_waist_yaw.STL" />
      </geometry>
      <material
        name="">
        <color
          rgba="0.752941176470588 0.752941176470588 0.752941176470588 1" />
      </material>
    </visual>
    <collision>
      <origin
        xyz="0 0 0"
        rpy="0 0 0" />
      <geometry>
        <mesh
          filename="package://surenaVgazebo/meshes/L_waist_yaw.STL" />
      </geometry>
    </collision>
    <gazebo reference="L_waist_yaw">
      <material>Gazebo/Yellow</material>
      <turnGravityOff>true</turnGravityOff>
    </gazebo>
  </link>
  <joint
    name="J_waist_yaw"
    type="continuous">
    <origin
      xyz="-0.025149 0 0.95712"
      rpy="0 0 0" />
    <parent
      link="pelvis" />
    <child
      link="L_waist_yaw" />
    <axis
      xyz="0 0 -1" />
    <limit effort="300.0" lower="-5000" upper="-5000" velocity="0.5"/>
  </joint>
  <transmission name="J13t">
    <type>transmission_interface/SimpleTransmission</type>
    <actuator name="motor13">
      <mechanicalReduction>1</mechanicalReduction>
      <hardwareInterface>hardware_interface/EffortJointInterface</hardwareInterface>
    </actuator>
    <joint name="J_waist_yaw">
      <hardwareInterface>hardware_interface/EffortJointInterface</hardwareInterface>
    </joint>
  </transmission>
  <link
    name="L_waist_pitch">
    <inertial>
      <origin
        xyz="-0.0444302421333388 -0.0080448098592892 -0.00604390988131424"
        rpy="0 0 0" />
      <mass
        value="0.527113051374615" />
      <inertia
        ixx="0.00015099462428363"
        ixy="-5.99718476651018E-07"
        ixz="-1.03332815503189E-05"
        iyy="0.000280944716444004"
        iyz="-3.19283122286598E-07"
        izz="0.000270390628387166" />
    </inertial>
    <visual>
      <origin
        xyz="0 0 0"
        rpy="0 0 0" />
      <geometry>
        <mesh
          filename="package://surenaVgazebo/meshes/L_waist_pitch.STL" />
      </geometry>
      <material
        name="">
        <color
          rgba="0.752941176470588 0.752941176470588 0.752941176470588 1" />
      </material>
    </visual>
    <collision>
      <origin
        xyz="0 0 0"
        rpy="0 0 0" />
      <geometry>
        <mesh
          filename="package://surenaVgazebo/meshes/L_waist_pitch.STL" />
      </geometry>
    </collision>
    <gazebo reference="L_waist_pitch">
      <material>Gazebo/Yellow</material>
      <turnGravityOff>true</turnGravityOff>
    </gazebo>
  </link>
  <joint
    name="J_waist_pitch"
    type="continuous">
    <origin
      xyz="0.044 0 0.051414"
      rpy="0 0 0" />
    <parent
      link="L_waist_yaw" />
    <child
      link="L_waist_pitch" />
    <axis
      xyz="0 -1 0" />
    <limit effort="300.0" lower="-5000" upper="-5000" velocity="0.5"/>
  </joint>
  <transmission name="J14t">
    <type>transmission_interface/SimpleTransmission</type>
    <actuator name="motor14">
      <mechanicalReduction>1</mechanicalReduction>
      <hardwareInterface>hardware_interface/EffortJointInterface</hardwareInterface>
    </actuator>
    <joint name="J_waist_pitch">
      <hardwareInterface>hardware_interface/EffortJointInterface</hardwareInterface>
    </joint>
  </transmission>
  <link
    name="L_waist_roll">
    <inertial>
      <origin
        xyz="0.00828259484101014 -0.00215026232182087 0.157273647916395"
        rpy="0 0 0" />
      <mass
        value="6.64856946990287" />
      <inertia
        ixx="0.0113118851820871"
        ixy="-1.44906144593437E-05"
        ixz="5.00608397117114E-06"
        iyy="0.00914576633624614"
        iyz="3.6416119481145E-05"
        izz="0.00843887642565412" />
    </inertial>
    <visual>
      <origin
        xyz="0 0 0"
        rpy="0 0 0" />
      <geometry>
        <mesh
          filename="package://surenaVgazebo/meshes/L_waist_roll.STL" />
      </geometry>
      <material
        name="">
        <color
          rgba="0.752941176470588 0.752941176470588 0.752941176470588 1" />
      </material>
    </visual>
    <collision>
      <origin
        xyz="0 0 0"
        rpy="0 0 0" />
      <geometry>
        <mesh
          filename="package://surenaVgazebo/meshes/L_waist_roll.STL" />
      </geometry>
    </collision>
    <gazebo reference="L_waist_roll">
      <material>Gazebo/Yellow</material>
      <turnGravityOff>true</turnGravityOff>
    </gazebo>
  </link>
  <joint
    name="J_waist_roll"
    type="continuous">
    <origin
      xyz="0 0 0"
      rpy="0 0 0" />
    <parent
      link="L_waist_pitch" />
    <child
      link="L_waist_roll" />
    <axis
      xyz="-1 0 0" />
    <limit effort="300.0" lower="-5000" upper="-5000" velocity="0.5"/>
  </joint>
  <transmission name="J15t">
    <type>transmission_interface/SimpleTransmission</type>
    <actuator name="motor15">
      <mechanicalReduction>1</mechanicalReduction>
      <hardwareInterface>hardware_interface/EffortJointInterface</hardwareInterface>
    </actuator>
    <joint name="J_waist_roll">
      <hardwareInterface>hardware_interface/EffortJointInterface</hardwareInterface>
    </joint>
  </transmission>
  <link
    name="RL_sh_pitch">
    <inertial>
      <origin
        xyz="-0.00548080540929836 -0.0393054889284084 -3.31441572187785E-07"
        rpy="0 0 0" />
      <mass
        value="0.241744696722351" />
      <inertia
        ixx="0.000145227506526578"
        ixy="-6.85992381565334E-07"
        ixz="-2.03206361852521E-08"
        iyy="9.78620561857312E-05"
        iyz="7.39415803945817E-08"
        izz="0.000101782723503229" />
    </inertial>
    <visual>
      <origin
        xyz="0 0 0"
        rpy="0 0 0" />
      <geometry>
        <mesh
          filename="package://surenaVgazebo/meshes/RL_sh_pitch.STL" />
      </geometry>
      <material
        name="">
        <color
          rgba="0.752941176470588 0.752941176470588 0.752941176470588 1" />
      </material>
    </visual>
    <collision>
      <origin
        xyz="0 0 0"
        rpy="0 0 0" />
      <geometry>
        <mesh
          filename="package://surenaVgazebo/meshes/RL_sh_pitch.STL" />
      </geometry>
    </collision>
    <gazebo reference="RL_sh_pitch">
      <material>Gazebo/Yellow</material>
      <turnGravityOff>true</turnGravityOff>
    </gazebo>
  </link>
  <joint
    name="RJ_sh_pitch"
    type="continuous">
    <origin
      xyz="0.006 -0.18503 0.28128"
      rpy="-0.1776 0 0" />
    <parent
      link="L_waist_roll" />
    <child
      link="RL_sh_pitch" />
    <axis
      xyz="0 -1 0" />
    <limit effort="300.0" lower="-5000" upper="-5000" velocity="0.5"/>
  </joint>
  <transmission name="J16t">
    <type>transmission_interface/SimpleTransmission</type>
    <actuator name="motor16">
      <mechanicalReduction>1</mechanicalReduction>
      <hardwareInterface>hardware_interface/EffortJointInterface</hardwareInterface>
    </actuator>
    <joint name="RJ_sh_pitch">
      <hardwareInterface>hardware_interface/EffortJointInterface</hardwareInterface>
    </joint>
  </transmission>
  <link
    name="RL_sh_roll">
    <inertial>
      <origin
        xyz="0.00637438049641992 0.00338309535467607 -0.0794620533767267"
        rpy="0 0 0" />
      <mass
        value="0.269096722395236" />
      <inertia
        ixx="0.000184829501585946"
        ixy="1.55141358108703E-07"
        ixz="6.83649897041583E-07"
        iyy="0.000191226361293168"
        iyz="-5.75197907550134E-08"
        izz="0.000135303189409154" />
    </inertial>
    <visual>
      <origin
        xyz="0 0 0"
        rpy="0 0 0" />
      <geometry>
        <mesh
          filename="package://surenaVgazebo/meshes/RL_sh_roll.STL" />
      </geometry>
      <material
        name="">
        <color
          rgba="0.752941176470588 0.752941176470588 0.752941176470588 1" />
      </material>
    </visual>
    <collision>
      <origin
        xyz="0 0 0"
        rpy="0 0 0" />
      <geometry>
        <mesh
          filename="package://surenaVgazebo/meshes/RL_sh_roll.STL" />
      </geometry>
    </collision>
    <gazebo reference="RL_sh_roll">
      <material>Gazebo/Yellow</material>
      <turnGravityOff>true</turnGravityOff>
    </gazebo>
  </link>
  <joint
    name="RJ_sh_roll"
    type="continuous">
    <origin
      xyz="0 -0.05 0"
      rpy="0.17412 0 0" />
    <parent
      link="RL_sh_pitch" />
    <child
      link="RL_sh_roll" />
    <axis
      xyz="-1 0 0" />
    <limit effort="300.0" lower="-5000" upper="-5000" velocity="0.5"/>
  </joint>
  <transmission name="J17t">
    <type>transmission_interface/SimpleTransmission</type>
    <actuator name="motor17">
      <mechanicalReduction>1</mechanicalReduction>
      <hardwareInterface>hardware_interface/EffortJointInterface</hardwareInterface>
    </actuator>
    <joint name="RJ_sh_roll">
      <hardwareInterface>hardware_interface/EffortJointInterface</hardwareInterface>
    </joint>
  </transmission>
  <link
    name="RL_sh_yaw">
    <inertial>
      <origin
        xyz="-0.000441981553929639 -0.0053189268563322 -0.0904566768350916"
        rpy="0 0 0" />
      <mass
        value="0.285150947148383" />
      <inertia
        ixx="0.00014852761999732"
        ixy="6.87643553827807E-07"
        ixz="-9.29779210984013E-08"
        iyy="0.000189568291465349"
        iyz="-1.59290393064121E-06"
        izz="9.03102579958398E-05" />
    </inertial>
    <visual>
      <origin
        xyz="0 0 0"
        rpy="0 0 0" />
      <geometry>
        <mesh
          filename="package://surenaVgazebo/meshes/RL_sh_yaw.STL" />
      </geometry>
      <material
        name="">
        <color
          rgba="0.752941176470588 0.752941176470588 0.752941176470588 1" />
      </material>
    </visual>
    <collision>
      <origin
        xyz="0 0 0"
        rpy="0 0 0" />
      <geometry>
        <mesh
          filename="package://surenaVgazebo/meshes/RL_sh_yaw.STL" />
      </geometry>
    </collision>
    <gazebo reference="RL_sh_yaw">
      <material>Gazebo/Yellow</material>
      <turnGravityOff>true</turnGravityOff>
    </gazebo>
  </link>
  <joint
    name="RJ_sh_yaw"
    type="continuous">
    <origin
      xyz="-0.0020041 0.0030573 -0.10984"
      rpy="0 0 0" />
    <parent
      link="RL_sh_roll" />
    <child
      link="RL_sh_yaw" />
    <axis
      xyz="0 0 -1" />
    <limit effort="300.0" lower="-5000" upper="-5000" velocity="0.5"/>
  </joint>
  <transmission name="J18t">
    <type>transmission_interface/SimpleTransmission</type>
    <actuator name="motor18">
      <mechanicalReduction>1</mechanicalReduction>
      <hardwareInterface>hardware_interface/EffortJointInterface</hardwareInterface>
    </actuator>
    <joint name="RJ_sh_yaw">
      <hardwareInterface>hardware_interface/EffortJointInterface</hardwareInterface>
    </joint>
  </transmission>
  <link
    name="RL_elbow_pitch">
    <inertial>
      <origin
        xyz="0.00493022613233483 -0.0102551314554704 -0.0365558337927716"
        rpy="0 0 0" />
      <mass
        value="0.0488471081132685" />
      <inertia
        ixx="2.17792144107569E-05"
        ixy="4.23726839799331E-13"
        ixz="1.59216815577834E-06"
        iyy="2.29177934934053E-05"
        iyz="-8.22267160836232E-13"
        izz="9.24497279497304E-06" />
    </inertial>
    <visual>
      <origin
        xyz="0 0 0"
        rpy="0 0 0" />
      <geometry>
        <mesh
          filename="package://surenaVgazebo/meshes/RL_elbow_pitch.STL" />
      </geometry>
      <material
        name="">
        <color
          rgba="0.752941176470588 0.752941176470588 0.752941176470588 1" />
      </material>
    </visual>
    <collision>
      <origin
        xyz="0 0 0"
        rpy="0 0 0" />
      <geometry>
        <mesh
          filename="package://surenaVgazebo/meshes/RL_elbow_pitch.STL" />
      </geometry>
    </collision>
    <gazebo reference="RL_elbow_pitch">
      <material>Gazebo/Yellow</material>
      <turnGravityOff>true</turnGravityOff>
    </gazebo>
  </link>
  <joint
    name="RJ_elbow_pitch"
    type="continuous">
    <origin
      xyz="0 0 -0.14696"
      rpy="0 0 0" />
    <parent
      link="RL_sh_yaw" />
    <child
      link="RL_elbow_pitch" />
    <axis
      xyz="0 1 0" />
    <limit effort="300.0" lower="-5000" upper="-5000" velocity="0.5"/>
  </joint>
  <transmission name="J19t">
    <type>transmission_interface/SimpleTransmission</type>
    <actuator name="motor19">
      <mechanicalReduction>1</mechanicalReduction>
      <hardwareInterface>hardware_interface/EffortJointInterface</hardwareInterface>
    </actuator>
    <joint name="RJ_elbow_pitch">
      <hardwareInterface>hardware_interface/EffortJointInterface</hardwareInterface>
    </joint>
  </transmission>
  <link
    name="RL_wrist_yaw">
    <inertial>
      <origin
        xyz="-0.000452327054415461 -0.00574138438323057 -0.0768990443011348"
        rpy="0 0 0" />
      <mass
        value="0.191890449250754" />
      <inertia
        ixx="8.79064778648649E-05"
        ixy="-1.61719714254971E-12"
        ixz="2.55487916664227E-07"
        iyy="8.3797631992618E-05"
        iyz="-5.1422730738444E-07"
        izz="4.67549144697618E-05" />
    </inertial>
    <visual>
      <origin
        xyz="0 0 0"
        rpy="0 0 0" />
      <geometry>
        <mesh
          filename="package://surenaVgazebo/meshes/RL_wrist_yaw.STL" />
      </geometry>
      <material
        name="">
        <color
          rgba="0.752941176470588 0.752941176470588 0.752941176470588 1" />
      </material>
    </visual>
    <collision>
      <origin
        xyz="0 0 0"
        rpy="0 0 0" />
      <geometry>
        <mesh
          filename="package://surenaVgazebo/meshes/RL_wrist_yaw.STL" />
      </geometry>
    </collision>
    <gazebo reference="RL_wrist_yaw">
      <material>Gazebo/Yellow</material>
      <turnGravityOff>true</turnGravityOff>
    </gazebo>
  </link>
  <joint
    name="RJ_wrist_yaw"
    type="continuous">
    <origin
      xyz="0.011503 -0.00275 -0.065234"
      rpy="0 -0.17453 0" />
    <parent
      link="RL_elbow_pitch" />
    <child
      link="RL_wrist_yaw" />
    <axis
      xyz="0 0 -1" />
    <limit effort="300.0" lower="-5000" upper="-5000" velocity="0.5"/>
  </joint>
  <transmission name="J20t">
    <type>transmission_interface/SimpleTransmission</type>
    <actuator name="motor20">
      <mechanicalReduction>1</mechanicalReduction>
      <hardwareInterface>hardware_interface/EffortJointInterface</hardwareInterface>
    </actuator>
    <joint name="RJ_wrist_yaw">
      <hardwareInterface>hardware_interface/EffortJointInterface</hardwareInterface>
    </joint>
  </transmission>
  <link
    name="RL_wrist_roll">
    <inertial>
      <origin
        xyz="2.24084724766427E-05 5.55111512312578E-17 0"
        rpy="0 0 0" />
      <mass
        value="0.00242703560719802" />
      <inertia
        ixx="2.2285886013701E-07"
        ixy="1.69069519088502E-23"
        ixz="1.65436122510606E-23"
        iyy="6.96864529769121E-08"
        iyz="-1.18385684759233E-22"
        izz="1.75573619124725E-07" />
    </inertial>
    <visual>
      <origin
        xyz="0 0 0"
        rpy="0 0 0" />
      <geometry>
        <mesh
          filename="package://surenaVgazebo/meshes/RL_wrist_roll.STL" />
      </geometry>
      <material
        name="">
        <color
          rgba="0.792156862745098 0.819607843137255 0.933333333333333 1" />
      </material>
    </visual>
    <collision>
      <origin
        xyz="0 0 0"
        rpy="0 0 0" />
      <geometry>
        <mesh
          filename="package://surenaVgazebo/meshes/RL_wrist_roll.STL" />
      </geometry>
    </collision>
    <gazebo reference="RL_wrist_roll">
      <material>Gazebo/Yellow</material>
      <turnGravityOff>true</turnGravityOff>
    </gazebo>
  </link>
  <joint
    name="RJ_wrist_roll"
    type="continuous">
    <origin
      xyz="0 -0.0081642 -0.15377"
      rpy="0 0 0" />
    <parent
      link="RL_wrist_yaw" />
    <child
      link="RL_wrist_roll" />
    <axis
      xyz="1 0 0" />
    <limit effort="300.0" lower="-5000" upper="-5000" velocity="0.5"/>
  </joint>
  <transmission name="J21t">
    <type>transmission_interface/SimpleTransmission</type>
    <actuator name="motor21">
      <mechanicalReduction>1</mechanicalReduction>
      <hardwareInterface>hardware_interface/EffortJointInterface</hardwareInterface>
    </actuator>
    <joint name="RJ_wrist_roll">
      <hardwareInterface>hardware_interface/EffortJointInterface</hardwareInterface>
    </joint>
  </transmission>
  <link
    name="RL_wrist_pitch">
    <inertial>
      <origin
        xyz="0.0068750358519937 0.00109265722849203 -0.0142564717400067"
        rpy="0 0 0" />
      <mass
        value="0.0116099116677997" />
      <inertia
        ixx="2.33511533106845E-06"
        ixy="1.21694622624511E-09"
        ixz="-6.18523505716608E-07"
        iyy="2.79402655664356E-06"
        iyz="1.50114931560208E-09"
        izz="2.97854995635386E-06" />
    </inertial>
    <visual>
      <origin
        xyz="0 0 0"
        rpy="0 0 0" />
      <geometry>
        <mesh
          filename="package://surenaVgazebo/meshes/RL_wrist_pitch.STL" />
      </geometry>
      <material
        name="">
        <color
          rgba="0.792156862745098 0.819607843137255 0.933333333333333 1" />
      </material>
    </visual>
    <collision>
      <origin
        xyz="0 0 0"
        rpy="0 0 0" />
      <geometry>
        <mesh
          filename="package://surenaVgazebo/meshes/RL_wrist_pitch.STL" />
      </geometry>
    </collision>
    <gazebo reference="RL_wrist_pitch">
      <material>Gazebo/Yellow</material>
      <turnGravityOff>true</turnGravityOff>
    </gazebo>
  </link>
  <joint
    name="RJ_wrist_pitch"
    type="continuous">
    <origin
      xyz="0 0 0"
      rpy="0 0 0" />
    <parent
      link="RL_wrist_roll" />
    <child
      link="RL_wrist_pitch" />
    <axis
      xyz="0 -1 0" />
    <limit effort="300.0" lower="-5000" upper="-5000" velocity="0.5"/>
  </joint>
  <transmission name="J22t">
    <type>transmission_interface/SimpleTransmission</type>
    <actuator name="motor22">
      <mechanicalReduction>1</mechanicalReduction>
      <hardwareInterface>hardware_interface/EffortJointInterface</hardwareInterface>
    </actuator>
    <joint name="RJ_wrist_pitch">
      <hardwareInterface>hardware_interface/EffortJointInterface</hardwareInterface>
    </joint>
  </transmission>
  <link
    name="LL_sh_pitch">
    <inertial>
      <origin
        xyz="-0.00548633483261682 0.0600743829134472 5.25073914235397E-05"
        rpy="0 0 0" />
      <mass
        value="0.241744696816416" />
      <inertia
        ixx="0.000145892143603691"
        ixy="6.84772315354999E-07"
        ixz="-4.56091661736664E-08"
        iyy="9.79255334581675E-05"
        iyz="5.15425418910702E-07"
        izz="0.000101054609213653" />
    </inertial>
    <visual>
      <origin
        xyz="0 0 0"
        rpy="0 0 0" />
      <geometry>
        <mesh
          filename="package://surenaVgazebo/meshes/LL_sh_pitch.STL" />
      </geometry>
      <material
        name="">
        <color
          rgba="0.752941176470588 0.752941176470588 0.752941176470588 1" />
      </material>
    </visual>
    <collision>
      <origin
        xyz="0 0 0"
        rpy="0 0 0" />
      <geometry>
        <mesh
          filename="package://surenaVgazebo/meshes/LL_sh_pitch.STL" />
      </geometry>
    </collision>
    <gazebo reference="LL_sh_pitch">
      <material>Gazebo/Yellow</material>
      <turnGravityOff>true</turnGravityOff>
    </gazebo>
  </link>
  <joint
    name="LJ_sh_pitch"
    type="continuous">
    <origin
      xyz="0.006 0.1616 0.27647"
      rpy="0.17063 0 0" />
    <parent
      link="L_waist_roll" />
    <child
      link="LL_sh_pitch" />
    <axis
      xyz="0 -1 0" />
    <limit effort="300.0" lower="-5000" upper="-5000" velocity="0.5"/>
  </joint>
  <transmission name="J23t">
    <type>transmission_interface/SimpleTransmission</type>
    <actuator name="motor23">
      <mechanicalReduction>1</mechanicalReduction>
      <hardwareInterface>hardware_interface/EffortJointInterface</hardwareInterface>
    </actuator>
    <joint name="LJ_sh_pitch">
      <hardwareInterface>hardware_interface/EffortJointInterface</hardwareInterface>
    </joint>
  </transmission>
  <link
    name="LL_sh_roll">
    <inertial>
      <origin
        xyz="-0.00274002778898313 0.000375740747527387 -0.0789243721610676"
        rpy="0 0 0" />
      <mass
        value="0.269096722390861" />
      <inertia
        ixx="0.000184836520632276"
        ixy="2.3118460818055E-07"
        ixz="-6.82587968980432E-07"
        iyy="0.000191219342243323"
        iyz="6.8744453820797E-08"
        izz="0.000135303189407402" />
    </inertial>
    <visual>
      <origin
        xyz="0 0 0"
        rpy="0 0 0" />
      <geometry>
        <mesh
          filename="package://surenaVgazebo/meshes/LL_sh_roll.STL" />
      </geometry>
      <material
        name="">
        <color
          rgba="0.752941176470588 0.752941176470588 0.752941176470588 1" />
      </material>
    </visual>
    <collision>
      <origin
        xyz="0 0 0"
        rpy="0 0 0" />
      <geometry>
        <mesh
          filename="package://surenaVgazebo/meshes/LL_sh_roll.STL" />
      </geometry>
    </collision>
    <gazebo reference="LL_sh_roll">
      <material>Gazebo/Yellow</material>
      <turnGravityOff>true</turnGravityOff>
    </gazebo>
  </link>
  <joint
    name="LJ_sh_roll"
    type="continuous">
    <origin
      xyz="0 0.067662 0"
      rpy="-0.17412 0 0" />
    <parent
      link="LL_sh_pitch" />
    <child
      link="LL_sh_roll" />
    <axis
      xyz="1 0 0" />
    <limit effort="300.0" lower="-5000" upper="-5000" velocity="0.5"/>
  </joint>
  <transmission name="J24t">
    <type>transmission_interface/SimpleTransmission</type>
    <actuator name="motor24">
      <mechanicalReduction>1</mechanicalReduction>
      <hardwareInterface>hardware_interface/EffortJointInterface</hardwareInterface>
    </actuator>
    <joint name="LJ_sh_roll">
      <hardwareInterface>hardware_interface/EffortJointInterface</hardwareInterface>
    </joint>
  </transmission>
  <link
    name="LL_sh_yaw">
    <inertial>
      <origin
        xyz="-0.000441986475438423 0.00529696344135744 -0.0925285653311854"
        rpy="0 0 0" />
      <mass
        value="0.285150947147925" />
      <inertia
        ixx="0.000148527105538436"
        ixy="-6.8765427021166E-07"
        ixz="9.95556831813367E-08"
        iyy="0.000189568291465338"
        iyz="1.55113132645246E-06"
        izz="9.03107724546922E-05" />
    </inertial>
    <visual>
      <origin
        xyz="0 0 0"
        rpy="0 0 0" />
      <geometry>
        <mesh
          filename="package://surenaVgazebo/meshes/LL_sh_yaw.STL" />
      </geometry>
      <material
        name="">
        <color
          rgba="0.752941176470588 0.752941176470588 0.752941176470588 1" />
      </material>
    </visual>
    <collision>
      <origin
        xyz="0 0 0"
        rpy="0 0 0" />
      <geometry>
        <mesh
          filename="package://surenaVgazebo/meshes/LL_sh_yaw.STL" />
      </geometry>
    </collision>
    <gazebo reference="LL_sh_yaw">
      <material>Gazebo/Yellow</material>
      <turnGravityOff>true</turnGravityOff>
    </gazebo>
  </link>
  <joint
    name="LJ_sh_yaw"
    type="continuous">
    <origin
      xyz="-0.0020041 0 -0.10734"
      rpy="0 0 0" />
    <parent
      link="LL_sh_roll" />
    <child
      link="LL_sh_yaw" />
    <axis
      xyz="0 0 1" />
    <limit effort="300.0" lower="-5000" upper="-5000" velocity="0.5"/>
  </joint>
  <transmission name="J25t">
    <type>transmission_interface/SimpleTransmission</type>
    <actuator name="motor25">
      <mechanicalReduction>1</mechanicalReduction>
      <hardwareInterface>hardware_interface/EffortJointInterface</hardwareInterface>
    </actuator>
    <joint name="LJ_sh_yaw">
      <hardwareInterface>hardware_interface/EffortJointInterface</hardwareInterface>
    </joint>
  </transmission>
  <link
    name="LL_elbow_pitch">
    <inertial>
      <origin
        xyz="0.00493082849665792 0.00825513190873167 -0.0365592499706316"
        rpy="0 0 0" />
      <mass
        value="0.0488471081132685" />
      <inertia
        ixx="2.17792144107569E-05"
        ixy="4.23726837356156E-13"
        ixz="1.59216815577837E-06"
        iyy="2.29177934934053E-05"
        iyz="-8.22267167264728E-13"
        izz="9.24497279497305E-06" />
    </inertial>
    <visual>
      <origin
        xyz="0 0 0"
        rpy="0 0 0" />
      <geometry>
        <mesh
          filename="package://surenaVgazebo/meshes/LL_elbow_pitch.STL" />
      </geometry>
      <material
        name="">
        <color
          rgba="0.752941176470588 0.752941176470588 0.752941176470588 1" />
      </material>
    </visual>
    <collision>
      <origin
        xyz="0 0 0"
        rpy="0 0 0" />
      <geometry>
        <mesh
          filename="package://surenaVgazebo/meshes/LL_elbow_pitch.STL" />
      </geometry>
    </collision>
    <gazebo reference="LL_elbow_pitch">
      <material>Gazebo/Yellow</material>
      <turnGravityOff>true</turnGravityOff>
    </gazebo>
  </link>
  <joint
    name="LJ_elbow_pitch"
    type="continuous">
    <origin
      xyz="0 0 -0.14909"
      rpy="0 0 0" />
    <parent
      link="LL_sh_yaw" />
    <child
      link="LL_elbow_pitch" />
    <axis
      xyz="0 1 0" />
    <limit effort="300.0" lower="-5000" upper="-5000" velocity="0.5"/>
  </joint>
  <transmission name="J26t">
    <type>transmission_interface/SimpleTransmission</type>
    <actuator name="motor26">
      <mechanicalReduction>1</mechanicalReduction>
      <hardwareInterface>hardware_interface/EffortJointInterface</hardwareInterface>
    </actuator>
    <joint name="LJ_elbow_pitch">
      <hardwareInterface>hardware_interface/EffortJointInterface</hardwareInterface>
    </joint>
  </transmission>
  <link
    name="LL_wrist_yaw">
    <inertial>
      <origin
        xyz="0.000376786409590622 0.00589152969072584 -0.0841183653702996"
        rpy="0 0 0" />
      <mass
        value="0.191890449250754" />
      <inertia
        ixx="8.79064778648649E-05"
        ixy="-1.61719713292678E-12"
        ixz="2.55487916664256E-07"
        iyy="8.3799217503325E-05"
        iyz="-4.42884208874494E-07"
        izz="4.67533289590548E-05" />
    </inertial>
    <visual>
      <origin
        xyz="0 0 0"
        rpy="0 0 0" />
      <geometry>
        <mesh
          filename="package://surenaVgazebo/meshes/LL_wrist_yaw.STL" />
      </geometry>
      <material
        name="">
        <color
          rgba="0.752941176470588 0.752941176470588 0.752941176470588 1" />
      </material>
    </visual>
    <collision>
      <origin
        xyz="0 0 0"
        rpy="0 0 0" />
      <geometry>
        <mesh
          filename="package://surenaVgazebo/meshes/LL_wrist_yaw.STL" />
      </geometry>
    </collision>
    <gazebo reference="LL_wrist_yaw">
      <material>Gazebo/Yellow</material>
      <turnGravityOff>true</turnGravityOff>
    </gazebo>
  </link>
  <joint
    name="JL_wrist_yaw"
    type="continuous">
    <origin
      xyz="0.010249 0.00075 -0.058128"
      rpy="0 -0.17453 0" />
    <parent
      link="LL_elbow_pitch" />
    <child
      link="LL_wrist_yaw" />
    <axis
      xyz="0 0 1" />
    <limit effort="300.0" lower="-5000" upper="-5000" velocity="0.5"/>
  </joint>
  <transmission name="J27t">
    <type>transmission_interface/SimpleTransmission</type>
    <actuator name="motor27">
      <mechanicalReduction>1</mechanicalReduction>
      <hardwareInterface>hardware_interface/EffortJointInterface</hardwareInterface>
    </actuator>
    <joint name="JL_wrist_yaw">
      <hardwareInterface>hardware_interface/EffortJointInterface</hardwareInterface>
    </joint>
  </transmission>
  <link
    name="LL_wrist_roll">
    <inertial>
      <origin
        xyz="2.24084724764137E-05 -2.77555756156289E-17 2.77555756156289E-17"
        rpy="0 0 0" />
      <mass
        value="0.00258579729402853" />
      <inertia
        ixx="2.39950941508916E-07"
        ixy="1.69688016354084E-23"
        ixz="-5.9557004103818E-23"
        iyy="7.22625513305648E-08"
        iyz="-6.71732921362546E-24"
        izz="1.92480493704934E-07" />
    </inertial>
    <visual>
      <origin
        xyz="0 0 0"
        rpy="0 0 0" />
      <geometry>
        <mesh
          filename="package://surenaVgazebo/meshes/LL_wrist_roll.STL" />
      </geometry>
      <material
        name="">
        <color
          rgba="0.792156862745098 0.819607843137255 0.933333333333333 1" />
      </material>
    </visual>
    <collision>
      <origin
        xyz="0 0 0"
        rpy="0 0 0" />
      <geometry>
        <mesh
          filename="package://surenaVgazebo/meshes/LL_wrist_roll.STL" />
      </geometry>
    </collision>
    <gazebo reference="LL_wrist_roll">
      <material>Gazebo/Yellow</material>
      <turnGravityOff>true</turnGravityOff>
    </gazebo>
  </link>
  <joint
    name="LJ_wrist_roll"
    type="continuous">
    <origin
      xyz="0 0.00083577 -0.16099"
      rpy="0 0 0" />
    <parent
      link="LL_wrist_yaw" />
    <child
      link="LL_wrist_roll" />
    <axis
      xyz="1 0 0" />
    <limit effort="300.0" lower="-5000" upper="-5000" velocity="0.5"/>
  </joint>
  <transmission name="J28t">
    <type>transmission_interface/SimpleTransmission</type>
    <actuator name="motor28">
      <mechanicalReduction>1</mechanicalReduction>
      <hardwareInterface>hardware_interface/EffortJointInterface</hardwareInterface>
    </actuator>
    <joint name="LJ_wrist_roll">
      <hardwareInterface>hardware_interface/EffortJointInterface</hardwareInterface>
    </joint>
  </transmission>
  <link
    name="LL_wrist_pitch">
    <inertial>
      <origin
        xyz="0.00688083909182573 9.3353250767092E-05 -0.0146721529892506"
        rpy="0 0 0" />
      <mass
        value="0.0112809877130659" />
      <inertia
        ixx="2.22710039448816E-06"
        ixy="1.21855455266564E-09"
        ixz="-6.19484036951968E-07"
        iyy="2.71239140729548E-06"
        iyz="1.38594622989801E-09"
        izz="2.93234680511296E-06" />
    </inertial>
    <visual>
      <origin
        xyz="0 0 0"
        rpy="0 0 0" />
      <geometry>
        <mesh
          filename="package://surenaVgazebo/meshes/LL_wrist_pitch.STL" />
      </geometry>
      <material
        name="">
        <color
          rgba="0.792156862745098 0.819607843137255 0.933333333333333 1" />
      </material>
    </visual>
    <collision>
      <origin
        xyz="0 0 0"
        rpy="0 0 0" />
      <geometry>
        <mesh
          filename="package://surenaVgazebo/meshes/LL_wrist_pitch.STL" />
      </geometry>
    </collision>
    <gazebo reference="LL_wrist_pitch">
      <material>Gazebo/Yellow</material>
      <turnGravityOff>true</turnGravityOff>
    </gazebo>
  </link>
  <joint
    name="LJ_wrist_pitch"
    type="continuous">
    <origin
      xyz="0 0 0"
      rpy="0 0 0" />
    <parent
      link="LL_wrist_roll" />
    <child
      link="LL_wrist_pitch" />
    <axis
      xyz="0 -1 0" />
    <limit effort="300.0" lower="-5000" upper="-5000" velocity="0.5"/>
  </joint>
  <transmission name="J29t">
    <type>transmission_interface/SimpleTransmission</type>
    <actuator name="motor29">
      <mechanicalReduction>1</mechanicalReduction>
      <hardwareInterface>hardware_interface/EffortJointInterface</hardwareInterface>
    </actuator>
    <joint name="LJ_wrist_pitch">
      <hardwareInterface>hardware_interface/EffortJointInterface</hardwareInterface>
    </joint>
  </transmission>
<!-- Gazebo plugin for ROS Control -->
<gazebo>
  <plugin name="gazebo_ros_control" filename="libgazebo_ros_control.so">
    <robotNamespace>/surenaVgazebo</robotNamespace>
  </plugin>
</gazebo>

</robot>
